Workbook

Sheet Datos_limpios_200
A1: Encuestado | B1: Edad | C1: Dispositivo | D1: Horas pantalla promedio | E1: Día mayor uso | F1: Horas día mayor uso | G1: App más usada | H1: Otra app | I1: Horas redes sociales | J1: Rendimiento académico | K1: Afecta concentración | L1: Cuesta desconectarse | M1: Usa celular antes de dormir | N1: Observaciones limpieza
A2: 1 | B2: 20 | C2: iPhone | D2: 4 | E2: Lunes | F2: 6 | G2: Otra | H2: spotify | I2: 3 | J2: 7 | K2: Sí, un poco | L2: Sí, a veces | M2: Sí, todos los días | N2: Sin observaciones
A3: 2 | B3: 22 | C3: Android | D3: 6.2 | E3: Domingo | F3: 12 | G3: Netflix u otra plataforma de streaming | I3: 3.5 | J3: 5 | K3: Sí, un poco | L3: Sí, siempre | M3: Sí, todos los días | N3: Horas pantalla: Corregido: 62 → 6.2
A4: 3 | B4: 20 | C4: Android | D4: 5 | E4: Viernes | F4: 9 | G4: Instagram | I4: 5 | J4: 10 | K4: No afecta nada | L4: Casi nunca | M4: Sí, todos los días | N4: Horas pantalla: Corregido: 050 → 5.0
A5: 4 | B5: 25 | C5: Android | D5: 4 | E5: Domingo | F5: 6 | G5: TikTok | I5: 5 | J5: 7 | K5: Sí, mucho | L5: Sí, siempre | M5: Sí, todos los días | N5: Sin observaciones
A6: 5 | B6: 25 | C6: Android | D6: 2.2 | E6: Miércoles | F6: 5.1 | G6: Videojuegos | I6: 1.4 | J6: 7 | K6: Sí, un poco | L6: Sí, a veces | M6: Sí, varias veces por semana | N6: Sin observaciones
A7: 6 | B7: 20 | C7: Android | D7: 4 | E7: Jueves | F7: 6.3 | G7: WhatsApp | I7: 3.8 | J7: 7 | K7: No afecta demasiado | L7: Casi nunca | M7: Sí, varias veces por semana | N7: Sin observaciones
A8: 7 | B8: 31 | C8: Android | D8: 4.1 | E8: Lunes | F8: 5.5 | G8: Instagram | I8: 3.4 | J8: 6 | K8: Sí, mucho | L8: Casi nunca | M8: Sí, todos los días | N8: Sin observaciones
A9: 8 | B9: 18 | C9: Otro | D9: 5.8 | E9: Viernes | F9: 7 | G9: X / Twitter | I9: 2.9 | J9: 6 | K9: Sí, un poco | L9: Sí, siempre | M9: Sí, varias veces por semana | N9: Sin observaciones
A10: 9 | B10: 32 | C10: iPhone | D10: 2.6 | E10: Lunes | F10: 3.5 | G10: Netflix u otra plataforma de streaming | I10: 2 | J10: 8 | K10: Sí, un poco | L10: Casi nunca | M10: Sí, varias veces por semana | N10: Sin observaciones
A11: 10 | B11: 23 | C11: iPhone | D11: 6.7 | E11: Miércoles | F11: 9.9 | G11: X / Twitter | I11: 1.6 | J11: 6 | K11: Sí, un poco | L11: Sí, a veces | M11: Sí, todos los días | N11: Sin observaciones
A12: 11 | B12: 20 | C12: Android | D12: 5.6 | E12: Viernes | F12: 8.4 | G12: TikTok | I12: 1.8 | J12: 6 | K12: Sí, un poco | L12: Sí, a veces | M12: Sí, varias veces por semana | N12: Sin observaciones
A13: 12 | B13: 19 | C13: iPhone | D13: 5.4 | E13: Domingo | F13: 7.9 | G13: TikTok | I13: 2.7 | J13: 6 | K13: Sí, un poco | L13: Sí, siempre | M13: Sí, varias veces por semana | N13: Sin observaciones
A14: 13 | B14: 22 | C14: iPhone | D14: 5 | E14: Sábado | F14: 7.8 | G14: Instagram | I14: 3.5 | J14: 7 | K14: No afecta demasiado | L14: Sí, a veces | M14: Casi nunca | N14: Sin observaciones
... A85: 84 | B85: 20 | C85: Android | D85: 7.7 | E85: Domingo | F85: 10.6 | G85: WhatsApp | I85: 5.2 | J85: 5 | K85: Sí, mucho | L85: Sí, siempre | M85: Sí, todos los días | N85: Sin observaciones
A86: 85 | B86: 21 | C86: Android | D86: 8.2 | E86: Sábado | F86: 11.3 | G86: Otra | H86: Discord | I86: 5.3 | J86: 4 | K86: Sí, mucho | L86: Sí, siempre | M86: Sí, varias veces por semana | N86: Sin observaciones
A87: 86 | B87: 25 | C87: Android | D87: 6.9 | E87: Sábado | F87: 9.6 | G87: Netflix u otra plataforma de streaming | I87: 4.9 | J87: 4 | K87: No afecta nada | L87: Sí, siempre | M87: Sí, varias veces por semana | N87: Sin observaciones
A88: 87 | B88: 19 | C88: Android | D88: 6.5 | E88: Viernes | F88: 4.5 | G88: TikTok | I88: 3.5 | J88: 9 | K88: No afecta demasiado | L88: Sí, siempre | M88: Sí, todos los días | N88: Sin observaciones
A89: 88 | B89: 20 | C89: Android | D89: 8.2 | E89: Miércoles | F89: 11.3 | G89: TikTok | I89: 7 | J89: 3 | K89: Sí, mucho | L89: Casi nunca | M89: Sí, todos los días | N89: Sin observaciones
A90: 89 | B90: 38 | C90: iPhone | D90: 5 | E90: Lunes | F90: 5 | G90: WhatsApp | I90: 4 | J90: 7 | K90: Sí, un poco | L90: Sí, a veces | M90: Sí, todos los días | N90: Sin observaciones
A91: 90 | B91: 38 | C91: iPhone | D91: 5 | E91: Lunes | F91: 5 | G91: WhatsApp | I91: 4 | J91: 7 | K91: Sí, un poco | L91: Sí, a veces | M91: Sí, todos los días | N91: Sin observaciones
A92: 91 | B92: 38 | C92: iPhone | D92: 5 | E92: Lunes | F92: 5 | G92: WhatsApp | I92: 4 | J92: 7 | K92: Sí, un poco | L92: Sí, a veces | M92: Sí, todos los días | N92: Sin observaciones
A93: 92 | B93: 25 | C93: iPhone | D93: 9 | E93: Miércoles | F93: 9 | G93: Instagram | I93: 2.5 | J93: 5 | K93: Sí, mucho | L93: Sí, a veces | M93: Sí, todos los días | N93: Sin observaciones
A94: 93 | B94: 25 | C94: Android | D94: 4 | E94: Jueves | F94: 6 | G94: TikTok | I94: 2.5 | J94: 7 | K94: Sí, mucho | L94: Sí, a veces | M94: Sí, todos los días | N94: Sin observaciones
A95: 94 | B95: 25 | C95: iPhone | D95: 5 | E95: Viernes | F95: 7 | G95: Instagram | I95: 3.5 | J95: 1 | K95: No afecta demasiado | L95: Nunca | M95: Sí, varias veces por semana | N95: Sin observaciones
A96: 95 | B96: 23 | C96: iPhone | D96: 8.5 | E96: Viernes | F96: 8.4 | G96: Instagram | I96: 3.5 | J96: 9 | K96: No afecta demasiado | L96: Sí, a veces | M96: Sí, todos los días | N96: Sin observaciones
A97: 96 | B97: 16 | C97: iPhone | D97: 1 | E97: Domingo | F97: 1.5 | G97: Otra | H97: Pornhub | I97: 1 | J97: 1 | K97: No afecta nada | L97: Nunca | M97: Nunca | N97: Sin observaciones
A98: 97 | B98: 22 | C98: Android | D98: 3.5 | E98: Miércoles | F98: 5 | G98: WhatsApp | I98: 2 | J98: 10 | K98: Sí, un poco | L98: Sí, a veces | M98: Casi nunca | N98: Sin observaciones
A99: 98 | B99: 21 | C99: iPhone | D99: 6 | E99: Domingo | F99: 7.3 | G99: Instagram | I99: 2.4 | J99: 2 | K99: Sí, un poco | L99: Sí, siempre | M99: Sí, todos los días | N99: Sin observaciones
A100: 99 | B100: 26 | C100: Otro | D100: 6.8 | E100: Jueves | F100: 12.6 | G100: YouTube | I100: 8 | J100: 2 | K100: No afecta demasiado | L100: Sí, a veces | M100: Casi nunca | N100: Sin observaciones
A101: 100 | B101: 24 | C101: Android | D101: 5 | E101: Miércoles | F101: 5.6 | G101: TikTok | I101: 2.2 | J101: 9 | K101: Sí, un poco | L101: Casi nunca | M101: Nunca | N101: Sin observaciones
A102: 101 | B102: 22 | C102: Android | D102: 6.3 | E102: Lunes | F102: 10.4 | G102: YouTube | I102: 1.9 | J102: 4 | K102: No afecta demasiado | L102: Sí, a veces | M102: Sí, varias veces por semana | N102: Sin observaciones
A103: 102 | B103: 35 | C103: iPhone | D103: 5.7 | E103: Sábado | F103: 12.3 | G103: TikTok | I103: 4.8 | J103: 10 | K103: No afecta demasiado | L103: Sí, a veces | M103: Sí, varias veces por semana | N103: Sin observaciones
A104: 103 | B104: 19 | C104: Otro | D104: 7.1 | E104: Viernes | F104: 13.5 | G104: Instagram | I104: 4.3 | J104: 5 | K104: No afecta demasiado | L104: Casi nunca | M104: Sí, varias veces por semana | N104: Sin observaciones
A105: 104 | B105: 24 | C105: Otro | D105: 7 | E105: Lunes | F105: 9 | G105: TikTok | I105: 1.6 | J105: 10 | K105: Sí, un poco | L105: Nunca | M105: Nunca | N105: Sin observaciones
A106: 105 | B106: 18 | C106: Android | D106: 6.1 | E106: Lunes | F106: 8.6 | G106: X / Twitter | I106: 6.9 | J106: 5 | K106: Sí, mucho | L106: Sí, a veces | M106: Sí, todos los días | N106: Sin observaciones
A107: 106 | B107: 24 | C107: Otro | D107: 5 | E107: Martes | F107: 11.2 | G107: YouTube | I107: 5.9 | J107: 10 | K107: Sí, mucho | L107: Sí, a veces | M107: Casi nunca | N107: Sin observaciones
A108: 107 | B108: 31 | C108: Otro | D108: 9 | E108: Martes | F108: 7.8 | G108: WhatsApp | I108: 2.7 | J108: 6 | K108: No afecta demasiado | L108: Sí, a veces | M108: Nunca | N108: Sin observaciones
A109: 108 | B109: 26 | C109: Otro | D109: 9.2 | E109: Sábado | F109: 14 | G109: TikTok | I109: 7.3 | J109: 5 | K109: No afecta nada | L109: Nunca | M109: Casi nunca | N109: Sin observaciones
... A125: 124 | B125: 22 | C125: iPhone | D125: 4.6 | E125: Lunes | F125: 12.7 | G125: TikTok | I125: 2 | J125: 3 | K125: Sí, mucho | L125: Casi nunca | M125: Casi nunca | N125: Sin observaciones
...

Sheet Resumen_limpieza
A1: Resumen de limpieza de datos
A2: Archivo original | B2: Encuesta sobre bienestar digital y uso de pantallas (respuestas).xlsx
A3: Respuestas originales recibidas | B3: 297
A4: Muestra utilizada para el TP | B4: 200
A5: Criterio aplicado | B5: Se usaron las primeras 200 respuestas, limpiando formatos numéricos y corrigiendo errores evidentes de carga.
A6: Correcciones aplicadas | B6: Valores de horas imposibles por día (>24) se interpretaron como error de decimal. Ej.: 62 → 6,2; 050 → 5,0.
A8: Variable | B8: Media | C8: Mediana | D8: Mínimo | E8: Máximo | F8: Cantidad
A9: Horas pantalla promedio | B9: =AVERAGE(Datos_limpios_200!D2:D201) -> 5.633 | C9: =MEDIAN(Datos_limpios_200!D2:D201) -> 5.65 | D9: =MIN(Datos_limpios_200!D2:D201) -> 1 | E9: =MAX(Datos_limpios_200!D2:D201) -> 10 | F9: =COUNT(Datos_limpios_200!D2:D201) -> 200
A10: Horas día mayor uso | B10: =AVERAGE(Datos_limpios_200!F2:F201) -> 8.486 | C10: =MEDIAN(Datos_limpios_200!F2:F201) -> 8.4 | D10: =MIN(Datos_limpios_200!F2:F201) -> 1.5 | E10: =MAX(Datos_limpios_200!F2:F201) -> 14 | F10: =COUNT(Datos_limpios_200!F2:F201) -> 200
A11: Horas redes sociales | B11: =AVERAGE(Datos_limpios_200!I2:I201) -> 3.9225 | C11: =MEDIAN(Datos_limpios_200!I2:I201) -> 3.5 | D11: =MIN(Datos_limpios_200!I2:I201) -> 1 | E11: =MAX(Datos_limpios_200!I2:I201) -> 8 | F11: =COUNT(Datos_limpios_200!I2:I201) -> 200
A12: Rendimiento académico | B12: =AVERAGE(Datos_limpios_200!J2:J201) -> 5.66 | C12: =MEDIAN(Datos_limpios_200!J2:J201) -> 6 | D12: =MIN(Datos_limpios_200!J2:J201) -> 1 | E12: =MAX(Datos_limpios_200!J2:J201) -> 10 | F12: =COUNT(Datos_limpios_200!J2:J201) -> 200

Sheet Revision_y_no_usadas
A1: Fila original | B1: Estado | C1: Marca temporal | D1: Edad | E1: Dispositivo | F1: Horas pantalla promedio | G1: Día mayor uso | H1: Horas día mayor uso | I1: App más usada | J1: Otra app | K1: Horas redes sociales | L1: Rendimiento académico | M1: Afecta concentración | N1: Cuesta desconectarse | O1: Usa celular antes de dormir | P1: Observaciones
A2: 3 | B2: Usada en muestra de 200 | C2: 46185.512 | D2: 22 | E2: Android | F2: 62 | G2: Domingo | H2: 12 | I2: Netflix u otra plataforma de streaming | K2: 3.5 | L2: 5 | M2: Sí, un poco | N2: Sí, siempre | O2: Sí, todos los días | P2: Horas pantalla: Corregido: 62 → 6.2
A3: 4 | B3: Usada en muestra de 200 | C3: 46185.512 | D3: 20 | E3: Android | F3: 050 | G3: Viernes | H3: 9 | I3: Instagram | K3: 5 | L3: 10 | M3: No afecta nada | N3: Casi nunca | O3: Sí, todos los días | P3: Horas pantalla: Corregido: 050 → 5.0
A4: 202 | B4: No usada: excede la muestra requerida de 200 | C4: 46185.61 | D4: 18 | E4: Otro | F4: 2.7 | G4: Sábado | H4: 4.9 | I4: Facebook | K4: 6.5 | L4: 7 | M4: Sí, un poco | N4: Nunca | O4: Nunca | P4: Sin observaciones
A5: 203 | B5: No usada: excede la muestra requerida de 200 | C5: 46185.61 | D5: 28 | E5: Otro | F5: 4.7 | G5: Sábado | H5: 8.1 | I5: WhatsApp | K5: 3.2 | L5: 3 | M5: Sí, un poco | N5: Sí, siempre | O5: Sí, varias veces por semana | P5: Sin observaciones
A6: 204 | B6: No usada: excede la muestra requerida de 200 | C6: 46185.61 | D6: 17 | E6: Android | F6: 5.4 | G6: Lunes | H6: 7.7 | I6: Netflix u otra plataforma de streaming | K6: 6.1 | L6: 4 | M6: Sí, un poco | N6: Sí, a veces | O6: Sí, todos los días | P6: Sin observaciones
A7: 205 | B7: No usada: excede la muestra requerida de 200 | C7: 46185.61 | D7: 24 | E7: Android | F7: 3 | G7: Jueves | H7: 4.5 | I7: TikTok | K7: 7.5 | L7: 6 | M7: Sí, un poco | N7: Sí, siempre | O7: Sí, todos los días | P7: Sin observaciones
A8: 206 | B8: No usada: excede la muestra requerida de 200 | C8: 46185.61 | D8: 20 | E8: Android | F8: 2.4 | G8: Lunes | H8: 5 | I8: Videojuegos | K8: 1.2 | L8: 4 | M8: No afecta nada | N8: Nunca | O8: Sí, todos los días | P8: Sin observaciones
A9: 207 | B9: No usada: excede la muestra requerida de 200 | C9: 46185.61 | D9: 28 | E9: iPhone | F9: 10 | G9: Sábado | H9: 12 | I9: X / Twitter | K9: 6.2 | L9: 5 | M9: No afecta demasiado | N9: Nunca | O9: Sí, todos los días | P9: Sin observaciones
A10: 208 | B10: No usada: excede la muestra requerida de 200 | C10: 46185.61 | D10: 16 | E10: Otro | F10: 9.3 | G10: Viernes | H10: 12.6 | I10: Netflix u otra plataforma de streaming | K10: 5.7 | L10: 5 | M10: Sí, un poco | N10: Casi nunca | O10: Nunca | P10: Sin observaciones
A11: 209 | B11: No usada: excede la muestra requerida de 200 | C11: 46185.61 | D11: 27 | E11: Otro | F11: 5.2 | G11: Miércoles | H11: 6.3 | I11: TikTok | K11: 6.5 | L11: 6 | M11: Sí, un poco | N11: Sí, siempre | O11: Casi nunca | P11: Sin observaciones
A12: 210 | B12: No usada: excede la muestra requerida de 200 | C12: 46185.61 | D12: 29 | E12: iPhone | F12: 10 | G12: Jueves | H12: 9.9 | I12: Otra | J12: Twitch | K12: 4.1 | L12: 10 | M12: No afecta nada | N12: Sí, a veces | O12: Casi nunca | P12: Sin observaciones
A13: 211 | B13: No usada: excede la muestra requerida de 200 | C13: 46185.61 | D13: 26 | E13: Otro | F13: 6.7 | G13: Lunes | H13: 5.5 | I13: Netflix u otra plataforma de streaming | K13: 1.4 | L13: 7 | M13: Sí, mucho | N13: Nunca | O13: Sí, varias veces por semana | P13: Sin observaciones
A14: 212 | B14: No usada: excede la muestra requerida de 200 | C14: 46185.61 | D14: 16 | E14: Android | F14: 7.4 | G14: Viernes | H14: 4.8 | I14: WhatsApp | K14: 7.1 | L14: 1 | M14: Sí, un poco | N14: Casi nunca | O14: Casi nunca | P14: Sin observaciones
A15: 213 | B15: No usada: excede la muestra requerida de 200 | C15: 46185.61 | D15: 16 | E15: Otro | F15: 5.4 | G15: Domingo | H15: 11.3 | I15: Videojuegos | K15: 2.9 | L15: 7 | M15: No afecta demasiado | N15: Sí, a veces | O15: Nunca | P15: Sin observaciones
A16: 214 | B16: No usada: excede la muestra requerida de 200 | C16: 46185.61 | D16: 23 | E16: Otro | F16: 8.6 | G16: Miércoles | H16: 6.8 | I16: Google / Navegador | K16: 1.1 | L16: 3 | M16: Sí, un poco | N16: Casi nunca | O16: Casi nunca | P16: Sin observaciones
A17: 215 | B17: No usada: excede la muestra requerida de 200 | C17: 46185.61 | D17: 32 | E17: Otro | F17: 3.7 | G17: Domingo | H17: 5.7 | I17: WhatsApp | K17: 1.4 | L17: 9 | M17: No afecta demasiado | N17: Sí, siempre | O17: Sí, varias veces por semana | P17: Sin observaciones
A18: 216 | B18: No usada: excede la muestra requerida de 200 | C18: 46185.61 | D18: 32 | E18: Android | F18: 8.5 | G18: Jueves | H18: 9.1 | I18: YouTube | K18: 3.9 | L18: 1 | M18: No afecta demasiado | N18: Casi nunca | O18: Nunca | P18: Sin observaciones
A19: 217 | B19: No usada: excede la muestra requerida de 200 | C19: 46185.61 | D19: 28 | E19: Otro | F19: 3.2 | G19: Miércoles | H19: 11.8 | I19: Instagram | K19: 7.9 | L19: 9 | M19: Sí, un poco | N19: Sí, siempre | O19: Sí, varias veces por semana | P19: Sin observaciones
A20: 218 | B20: No usada: excede la muestra requerida de 200 | C20: 46185.61 | D20: 33 | E20: iPhone | F20: 9.6 | G20: Viernes | H20: 4.5 | I20: Otra | J20: Reddit | K20: 7.5 | L20: 2 | M20: Sí, un poco | N20: Casi nunca | O20: Nunca | P20: Sin observaciones
A21: 219 | B21: No usada: excede la muestra requerida de 200 | C21: 46185.61 | D21: 19 | E21: Android | F21: 4.2 | G21: Sábado | H21: 13.9 | I21: Netflix u otra plataforma de streaming | K21: 5.7 | L21: 1 | M21: No afecta demasiado | N21: Nunca | O21: Sí, varias veces por semana | P21: Sin observaciones
A22: 220 | B22: No usada: excede la muestra requerida de 200 | C22: 46185.61 | D22: 20 | E22: Android | F22: 3.8 | G22: Jueves | H22: 5.9 | I22: Otra | J22: Spotify | K22: 3.8 | L22: 9 | M22: No afecta nada | N22: Sí, siempre | O22: Nunca | P22: Sin observaciones
A23: 221 | B23: No usada: excede la muestra requerida de 200 | C23: 46185.61 | D23: 34 | E23: Android | F23: 5 | G23: Lunes | H23: 5.9 | I23: Instagram | K23: 3.6 | L23: 9 | M23: No afecta demasiado | N23: Sí, siempre | O23: Nunca | P23: Sin observaciones
A24: 222 | B24: No usada: excede la muestra requerida de 200 | C24: 46185.61 | D24: 29 | E24: Otro | F24: 5 | G24: Sábado | H24: 4.9 | I24: Netflix u otra plataforma de streaming | K24: 2.5 | L24: 5 | M24: Sí, mucho | N24: Nunca | O24: Sí, varias veces por semana | P24: Sin observaciones
A25: 223 | B25: No usada: excede la muestra requerida de 200 | C25: 46185.61 | D25: 31 | E25: iPhone | F25: 3.8 | G25: Lunes | H25: 4.2 | I25: WhatsApp | K25: 4.2 | L25: 1 | M25: No afecta nada | N25: Nunca | O25: Nunca | P25: Sin observaciones
A26: 224 | B26: No usada: excede la muestra requerida de 200 | C26: 46185.61 | D26: 20 | E26: Otro | F26: 4 | G26: Lunes | H26: 13.9 | I26: Otra | J26: Pinterest | K26: 6.2 | L26: 1 | M26: Sí, un poco | N26: Casi nunca | O26: Sí, varias veces por semana | P26: Sin observaciones
A27: 225 | B27: No usada: excede la muestra requerida de 200 | C27: 46185.61 | D27: 19 | E27: Android | F27: 3.2 | G27: Domingo | H27: 10.3 | I27: Netflix u otra plataforma de streaming | K27: 7.9 | L27: 8 | M27: Sí, un poco | N27: Nunca | O27: Casi nunca | P27: Sin observaciones
A28: 226 | B28: No usada: excede la muestra requerida de 200 | C28: 46185.61 | D28: 18 | E28: Otro | F28: 9.6 | G28: Viernes | H28: 5.9 | I28: Google / Navegador | K28: 7.7 | L28: 10 | M28: No afecta demasiado | N28: Sí, a veces | O28: Casi nunca | P28: Sin observaciones
A29: 227 | B29: No usada: excede la muestra requerida de 200 | C29: 46185.61 | D29: 27 | E29: Android | F29: 2.1 | G29: Miércoles | H29: 9.9 | I29: YouTube | K29: 6.1 | L29: 3 | M29: No afecta nada | N29: Casi nunca | O29: Nunca | P29: Sin observaciones
A30: 228 | B30: No usada: excede la muestra requerida de 200 | C30: 46185.61 | D30: 35 | E30: Android | F30: 4.2 | G30: Domingo | H30: 7.6 | I30: WhatsApp | K30: 4.9 | L30: 7 | M30: No afecta nada | N30: Sí, a veces | O30: Sí, varias veces por semana | P30: Sin observaciones
A31: 229 | B31: No usada: excede la muestra requerida de 200 | C31: 46185.61 | D31: 20 | E31: Android | F31: 8.7 | G31: Jueves | H31: 7.6 | I31: WhatsApp | K31: 4.8 | L31: 3 | M31: No afecta nada | N31: Casi nunca | O31: Sí, varias veces por semana | P31: Sin observaciones
A32: 230 | B32: No usada: excede la muestra requerida de 200 | C32: 46185.61 | D32: 20 | E32: Android | F32: 2.4 | G32: Lunes | H32: 6.1 | I32: Facebook | K32: 7.5 | L32: 2 | M32: No afecta nada | N32: Sí, a veces | O32: Sí, varias veces por semana | P32: Sin observaciones
A33: 231 | B33: No usada: excede la muestra requerida de 200 | C33: 46185.61 | D33: 17 | E33: Android | F33: 4.6 | G33: Sábado | H33: 5.5 | I33: Netflix u otra plataforma de streaming | K33: 3.1 | L33: 6 | M33: No afecta demasiado | N33: Sí, a veces | O33: Nunca | P33: Sin observaciones
A34: 232 | B34: No usada: excede la muestra requerida de 200 | C34: 46185.61 | D34: 18 | E34: Android | F34: 6.4 | G34: Viernes | H34: 11.3 | I34: WhatsApp | K34: 3.4 | L34: 5 | M34: No afecta demasiado | N34: Nunca | O34: Sí, todos los días | P34: Sin observaciones
A35: 233 | B35: No usada: excede la muestra requerida de 200 | C35: 46185.61 | D35: 18 | E35: iPhone | F35: 8.4 | G35: Jueves | H35: 12.7 | I35: WhatsApp | K35: 3.8 | L35: 7 | M35: No afecta demasiado | N35: Casi nunca | O35: Nunca | P35: Sin observaciones
A36: 234 | B36: No usada: excede la muestra requerida de 200 | C36: 46185.61 | D36: 18 | E36: iPhone | F36: 6.2 | G36: Domingo | H36: 4.3 | I36: Videojuegos | K36: 2.5 | L36: 3 | M36: No afecta demasiado | N36: Nunca | O36: Nunca | P36: Sin observaciones
A37: 235 | B37: No usada: excede la muestra requerida de 200 | C37: 46185.61 | D37: 22 | E37: Otro | F37: 7.9 | G37: Miércoles | H37: 13 | I37: Netflix u otra plataforma de streaming | K37: 7 | L37: 9 | M37: Sí, mucho | N37: Sí, a veces | O37: Nunca | P37: Sin observaciones
A38: 236 | B38: No usada: excede la muestra requerida de 200 | C38: 46185.61 | D38: 16 | E38: Android | F38: 9.4 | G38: Jueves | H38: 4.6 | I38: Netflix u otra plataforma de streaming | K38: 2.5 | L38: 2 | M38: No afecta nada | N38: Nunca | O38: Nunca | P38: Sin observaciones
... A51: 249 | B51: No usada: excede la muestra requerida de 200 | C51: 46185.611 | D51: 34 | E51: Otro | F51: 5 | G51: Sábado | H51: 13.9 | I51: TikTok | K51: 4.4 | L51: 7 | M51: No afecta demasiado | N51: Nunca | O51: Sí, varias veces por semana | P51: Sin observaciones
A52: 250 | B52: No usada: excede la muestra requerida de 200 | C52: 46185.611 | D52: 35 | E52: iPhone | F52: 2.9 | G52: Domingo | H52: 12.3 | I52: Otra | J52: Pinterest | K52: 5.1 | L52: 7 | M52: No afecta demasiado | N52: Casi nunca | O52: Casi nunca | P52: Sin observaciones
...

Sheet Datos_originales
A1: Marca temporal | B1: Edad | C1: Dispositivo | D1: Horas pantalla promedio | E1: Día mayor uso | F1: Horas día mayor uso | G1: App más usada | H1: Otra app | I1: Horas redes sociales | J1: Rendimiento académico | K1: Afecta concentración | L1: Cuesta desconectarse | M1: Usa celular antes de dormir
A2: 46185.509 | B2: 20 | C2: iPhone | D2: 4 | E2: Lunes | F2: 6 | G2: Otra | H2: spotify | I2: 3 | J2: 7 | K2: Sí, un poco | L2: Sí, a veces | M2: Sí, todos los días
A3: 46185.512 | B3: 22 | C3: Android | D3: 62 | E3: Domingo | F3: 12 | G3: Netflix u otra plataforma de streaming | I3: 3.5 | J3: 5 | K3: Sí, un poco | L3: Sí, siempre | M3: Sí, todos los días
A4: 46185.512 | B4: 20 | C4: Android | D4: 050 | E4: Viernes | F4: 9 | G4: Instagram | I4: 5 | J4: 10 | K4: No afecta nada | L4: Casi nunca | M4: Sí, todos los días
A5: 46185.521 | B5: 25 | C5: Android | D5: 4 | E5: Domingo | F5: 6 | G5: TikTok | I5: 5 | J5: 7 | K5: Sí, mucho | L5: Sí, siempre | M5: Sí, todos los días
A6: 46185.523 | B6: 25 | C6: Android | D6: 2.2 | E6: Miércoles | F6: 5.1 | G6: Videojuegos | I6: 1.4 | J6: 7 | K6: Sí, un poco | L6: Sí, a veces | M6: Sí, varias veces por semana
A7: 46185.523 | B7: 20 | C7: Android | D7: 4 | E7: Jueves | F7: 6.3 | G7: WhatsApp | I7: 3.8 | J7: 7 | K7: No afecta demasiado | L7: Casi nunca | M7: Sí, varias veces por semana
A8: 46185.523 | B8: 31 | C8: Android | D8: 4.1 | E8: Lunes | F8: 5.5 | G8: Instagram | I8: 3.4 | J8: 6 | K8: Sí, mucho | L8: Casi nunca | M8: Sí, todos los días
A9: 46185.523 | B9: 18 | C9: Otro | D9: 5.8 | E9: Viernes | F9: 7 | G9: X / Twitter | I9: 2.9 | J9: 6 | K9: Sí, un poco | L9: Sí, siempre | M9: Sí, varias veces por semana
A10: 46185.523 | B10: 32 | C10: iPhone | D10: 2.6 | E10: Lunes | F10: 3.5 | G10: Netflix u otra plataforma de streaming | I10: 2 | J10: 8 | K10: Sí, un poco | L10: Casi nunca | M10: Sí, varias veces por semana
A11: 46185.523 | B11: 23 | C11: iPhone | D11: 6.7 | E11: Miércoles | F11: 9.9 | G11: X / Twitter | I11: 1.6 | J11: 6 | K11: Sí, un poco | L11: Sí, a veces | M11: Sí, todos los días
A12: 46185.523 | B12: 20 | C12: Android | D12: 5.6 | E12: Viernes | F12: 8.4 | G12: TikTok | I12: 1.8 | J12: 6 | K12: Sí, un poco | L12: Sí, a veces | M12: Sí, varias veces por semana
A13: 46185.523 | B13: 19 | C13: iPhone | D13: 5.4 | E13: Domingo | F13: 7.9 | G13: TikTok | I13: 2.7 | J13: 6 | K13: Sí, un poco | L13: Sí, siempre | M13: Sí, varias veces por semana
A14: 46185.523 | B14: 22 | C14: iPhone | D14: 5 | E14: Sábado | F14: 7.8 | G14: Instagram | I14: 3.5 | J14: 7 | K14: No afecta demasiado | L14: Sí, a veces | M14: Casi nunca
A15: 46185.524 | B15: 17 | C15: Android | D15: 5.6 | E15: Sábado | F15: 7.8 | G15: WhatsApp | I15: 2.9 | J15: 7 | K15: Sí, un poco | L15: Sí, a veces | M15: Casi nunca
A16: 46185.524 | B16: 22 | C16: iPhone | D16: 5.1 | E16: Jueves | F16: 8.3 | G16: Instagram | I16: 3.3 | J16: 6 | K16: Sí, un poco | L16: Sí, siempre | M16: Casi nunca
... A23: 46185.524 | B23: 19 | C23: iPhone | D23: 3.8 | E23: Jueves | F23: 6.2 | G23: Instagram | I23: 3.4 | J23: 7 | K23: Sí, un poco | L23: Casi nunca | M23: Casi nunca
A24: 46185.524 | B24: 22 | C24: Android | D24: 3 | E24: Miércoles | F24: 2.5 | G24: Instagram | I24: 2 | J24: 7 | K24: No afecta demasiado | L24: Sí, a veces | M24: Sí, todos los días
A25: 46185.524 | B25: 19 | C25: Android | D25: 2.8 | E25: Martes | F25: 5.3 | G25: YouTube | I25: 1.1 | J25: 7 | K25: No afecta demasiado | L25: Sí, a veces | M25: Sí, todos los días
A26: 46185.524 | B26: 21 | C26: Android | D26: 2.3 | E26: Sábado | F26: 5 | G26: Instagram | I26: 1.8 | J26: 7 | K26: Sí, un poco | L26: Casi nunca | M26: Casi nunca
A27: 46185.524 | B27: 26 | C27: iPhone | D27: 3.5 | E27: Miércoles | F27: 5.9 | G27: YouTube | I27: 2.6 | J27: 6 | K27: Sí, un poco | L27: Casi nunca | M27: Sí, todos los días
A28: 46185.524 | B28: 20 | C28: Android | D28: 4.2 | E28: Miércoles | F28: 6.4 | G28: TikTok | I28: 2.4 | J28: 7 | K28: Sí, un poco | L28: Sí, a veces | M28: Sí, varias veces por semana
A29: 46185.524 | B29: 19 | C29: Android | D29: 8.5 | E29: Lunes | F29: 10.9 | G29: TikTok | I29: 2.9 | J29: 5 | K29: Sí, mucho | L29: Sí, siempre | M29: Sí, todos los días
A30: 46185.524 | B30: 21 | C30: Android | D30: 4.1 | E30: Domingo | F30: 5.8 | G30: Instagram | I30: 3.7 | J30: 6 | K30: Sí, un poco | L30: Casi nunca | M30: Casi nunca
A31: 46185.525 | B31: 20 | C31: Android | D31: 6.3 | E31: Domingo | F31: 8.5 | G31: TikTok | I31: 4.2 | J31: 5 | K31: Sí, un poco | L31: Sí, a veces | M31: Casi nunca
A32: 46185.525 | B32: 24 | C32: Android | D32: 6.2 | E32: Jueves | F32: 7.8 | G32: Instagram | I32: 5.3 | J32: 6 | K32: Sí, un poco | L32: Casi nunca | M32: Sí, todos los días
A33: 46185.525 | B33: 28 | C33: iPhone | D33: 6.6 | E33: Domingo | F33: 9.4 | G33: WhatsApp | I33: 3.6 | J33: 5 | K33: No afecta demasiado | L33: Sí, a veces | M33: Sí, todos los días
A34: 46185.525 | B34: 17 | C34: iPhone | D34: 8.2 | E34: Lunes | F34: 10 | G34: Instagram | I34: 3.2 | J34: 5 | K34: No afecta demasiado | L34: Sí, a veces | M34: Sí, varias veces por semana
A35: 46185.525 | B35: 28 | C35: Android | D35: 4.9 | E35: Domingo | F35: 7.1 | G35: Instagram | I35: 1.4 | J35: 7 | K35: Sí, un poco | L35: Casi nunca | M35: Sí, varias veces por semana
A36: 46185.525 | B36: 28 | C36: iPhone | D36: 6.6 | E36: Miércoles | F36: 8.9 | G36: Netflix u otra plataforma de streaming | I36: 2.5 | J36: 5 | K36: Sí, un poco | L36: Nunca | M36: Sí, todos los días
... A85: 46185.544 | B85: 20 | C85: Android | D85: 7.7 | E85: Domingo | F85: 10.6 | G85: WhatsApp | I85: 5.2 | J85: 5 | K85: Sí, mucho | L85: Sí, siempre | M85: Sí, todos los días
A86: 46185.544 | B86: 21 | C86: Android | D86: 8.2 | E86: Sábado | F86: 11.3 | G86: Otra | H86: Discord | I86: 5.3 | J86: 4 | K86: Sí, mucho | L86: Sí, siempre | M86: Sí, varias veces por semana
A87: 46185.545 | B87: 25 | C87: Android | D87: 6.9 | E87: Sábado | F87: 9.6 | G87: Netflix u otra plataforma de streaming | I87: 4.9 | J87: 4 | K87: No afecta nada | L87: Sí, siempre | M87: Sí, varias veces por semana
A88: 46185.545 | B88: 19 | C88: Android | D88: 6.5 | E88: Viernes | F88: 4.5 | G88: TikTok | I88: 3.5 | J88: 9 | K88: No afecta demasiado | L88: Sí, siempre | M88: Sí, todos los días
A89: 46185.545 | B89: 20 | C89: Android | D89: 8.2 | E89: Miércoles | F89: 11.3 | G89: TikTok | I89: 7 | J89: 3 | K89: Sí, mucho | L89: Casi nunca | M89: Sí, todos los días
A90: 46185.55 | B90: 38 | C90: iPhone | D90: 5 | E90: Lunes | F90: Por el trabajo uso más de 5 horas | G90: WhatsApp | I90: 4 | J90: 7 | K90: Sí, un poco | L90: Sí, a veces | M90: Sí, todos los días
A91: 46185.55 | B91: 38 | C91: iPhone | D91: 5 | E91: Lunes | F91: Por el trabajo uso más de 5 horas | G91: WhatsApp | I91: 4 | J91: 7 | K91: Sí, un poco | L91: Sí, a veces | M91: Sí, todos los días
A92: 46185.55 | B92: 38 | C92: iPhone | D92: 5 | E92: Lunes | F92: Por el trabajo uso más de 5 horas | G92: WhatsApp | I92: 4 | J92: 7 | K92: Sí, un poco | L92: Sí, a veces | M92: Sí, todos los días
A93: 46185.552 | B93: 25 | C93: iPhone | D93: 9 | E93: Miércoles | F93: 9 | G93: Instagram | I93: 2.5 | J93: 5 | K93: Sí, mucho | L93: Sí, a veces | M93: Sí, todos los días
A94: 46185.562 | B94: 25 | C94: Android | D94: 4 | E94: Jueves | F94: 6 | G94: TikTok | I94: 2.5 | J94: 7 | K94: Sí, mucho | L94: Sí, a veces | M94: Sí, todos los días
...

Sheet Desarrollo_1ra_etapa
A1: Trabajo Práctico Integrador - Primera etapa
A3: Variable estadística | B3: Cantidad de horas promedio de uso de pantalla por día. | E3: Consigna e) | F3: =COUNTIFS(Datos_limpios_200!$I$2:$I$201,">=3",Datos_limpios_200!$I$2:$I$201,"<=8") -> 125 | G3: ="Equivale a "&F3&" personas de la muestra." -> Equivale a 125 personas de la muestra.
A4: Tipo de variable | B4: Cuantitativa continua. | E4: Cantidad de estudiantes que utilizan entre 3 y 8 horas diarias las redes sociales | F4: =COUNTIF(Datos_limpios_200!$I$2:$I$201,">6")/COUNT(Datos_limpios_200!$I$2:$I$201) -> 0.165 | G4: ="Equivale al "&TEXT(F4,"0.00%")&" de la muestra." -> Equivale al 017% de la muestra.
A5: Escala de medición | B5: Escala de razón, porque posee cero absoluto y permite comparar proporciones. | E5: Porcentaje de estudiantes que utilizan más de 6 horas diarias las redes sociales | F5: =COUNTIF(Datos_limpios_200!$I$2:$I$201,"<2") -> 34 | G5: ="Equivale a "&F5&" personas de la muestra." -> Equivale a 34 personas de la muestra.
A6: Población | B6: Personas/estudiantes que utilizan celulares o dispositivos móviles. | E6: Cantidad de estudiantes que utilizan menos de 2 horas diarias las redes sociales | F6: =COUNTIFS(Datos_limpios_200!$I$2:$I$201,">=5",Datos_limpios_200!$I$2:$I$201,"<=10")/COUNT(Datos_limpios_200!$I$2:$I$201) -> 0.305 | G6: ="Equivale al "&TEXT(F6,"0.00%")&" de la muestra." -> Equivale al 031% de la muestra.
A7: Muestra | B7: 200 personas encuestadas mediante formulario digital. | E7: Porcentaje de estudiantes que utilizan entre 5 y 10 horas diarias las redes sociales | F7: =COUNTIF(Datos_limpios_200!$I$2:$I$201,">8") -> 0 | G7: ="Equivale a "&F7&" personas de la muestra." -> Equivale a 0 personas de la muestra.
A8: Unidad de observación | B8: Cada persona encuestada. | E8: Cantidad de estudiantes que utilizan más de 8 horas diarias las redes sociales | F8: =COUNTIF(Datos_limpios_200!$I$2:$I$201,"<4")/COUNT(Datos_limpios_200!$I$2:$I$201) -> 0.545 | G8: ="Equivale al "&TEXT(F8,"0.00%")&" de la muestra." -> Equivale al 055% de la muestra.
A9: Base utilizada | B9: Hoja Datos_limpios_200 del archivo limpio. | E9: Porcentaje de estudiantes que utilizan menos de 4 horas diarias las redes sociales | F9: =COUNTIFS(Datos_limpios_200!$I$2:$I$201,">=1",Datos_limpios_200!$I$2:$I$201,"<=6") -> 167 | G9: ="Equivale a "&F9&" personas de la muestra." -> Equivale a 167 personas de la muestra.
E10: Cantidad de estudiantes que utilizan entre 1 y 6 horas diarias las redes sociales | F10: =COUNTIF(Datos_limpios_200!$I$2:$I$201,">9")/COUNT(Datos_limpios_200!$I$2:$I$201) -> 0 | G10: ="Equivale al "&TEXT(F10,"0.00%")&" de la muestra." -> Equivale al 000% de la muestra.
A11: Medida | B11: Resultado | C11: Interpretación breve | E11: Porcentaje de estudiantes que utilizan más de 9 horas diarias las redes sociales | F11: 0 | G11: Equivale al 0.00% de la muestra.
A12: Media aritmética | B12: =AVERAGE(Datos_limpios_200!$D$2:$D$201) -> 5.633 | C12: ="En promedio, los encuestados utilizan "&ROUND(B12,2)&" horas de pantalla por día." -> En promedio, los encuestados utilizan 5,63 horas de pantalla por día.
A13: Moda | B13: 5 | C13: ="El valor que más se repite es "&ROUND(B13,2)&" horas." -> El valor que más se repite es 5 horas.
A14: Mediana | B14: =MEDIAN(Datos_limpios_200!$D$2:$D$201) -> 5.65 | C14: ="El 50% de la muestra utiliza hasta "&ROUND(B14,2)&" horas de pantalla por día." -> El 50% de la muestra utiliza hasta 5,65 horas de pantalla por día. | E14: Datos para la reflexión | F14: Resultado | G14: Interpretación
A15: Coeficiente de asimetría | B15: =SKEW(Datos_limpios_200!$D$2:$D$201) -> 0.083800534 | C15: ="Indica si la distribución se inclina hacia valores bajos o altos. Resultado: "&ROUND(B15,3) -> Indica si la distribución se inclina hacia valores bajos o altos. Resultado: 0,084 | E15: Día con mayor uso más frecuente | F15: Lunes | G15: Fue el día más repetido entre las respuestas (37 casos).
A16: Curtosis | B16: =KURT(Datos_limpios_200!$D$2:$D$201) -> -0.94592289 | C16: ="Mide el grado de concentración o aplanamiento de los datos. Resultado: "&ROUND(B16,3) -> Mide el grado de concentración o aplanamiento de los datos. Resultado: -0,946 | E16: Aplicación más utilizada | F16: Instagram | G16: La moda de la variable app más usada es Instagram (41 casos).
A17: Varianza | B17: =VAR(Datos_limpios_200!$D$2:$D$201) -> 4.456192 | C17: ="Mide la dispersión cuadrática de las horas respecto de la media. Resultado: "&ROUND(B17,3) -> Mide la dispersión cuadrática de las horas respecto de la media. Resultado: 4,456 | E17: ¿Alguna medida supera 3 horas? | F17: Sí | G17: La media de pantalla es 5.63 horas, superior a 3 horas.
A18: Desvío estándar | B18: =STDEV(Datos_limpios_200!$D$2:$D$201) -> 2.1109694 | C18: ="Los datos se alejan aproximadamente "&ROUND(B18,2)&" horas de la media." -> Los datos se alejan aproximadamente 2,11 horas de la media.
A19: Coeficiente de variación | B19: =B18/B12 -> 0.37475048 | C19: ="La variabilidad relativa es de "&ROUND(B19*100,2)&"% respecto de la media." -> La variabilidad relativa es de 37,48% respecto de la media.
A20: Q1 | B20: =QUARTILE(Datos_limpios_200!$D$2:$D$201,1) -> 3.875 | C20: ="El 25% de los encuestados utiliza hasta "&ROUND(B20,2)&" horas de pantalla." -> El 25% de los encuestados utiliza hasta 3,88 horas de pantalla.
A21: Q3 | B21: =QUARTILE(Datos_limpios_200!$D$2:$D$201,3) -> 7.1 | C21: ="El 75% de los encuestados utiliza hasta "&ROUND(B21,2)&" horas de pantalla." -> El 75% de los encuestados utiliza hasta 7,1 horas de pantalla.
A22: D3 | B22: =PERCENTILE(Datos_limpios_200!$D$2:$D$201,0.3) -> 4 | C22: ="El 30% de la muestra utiliza hasta "&ROUND(B22,2)&" horas de pantalla." -> El 30% de la muestra utiliza hasta 4 horas de pantalla.
A23: D4 | B23: =PERCENTILE(Datos_limpios_200!$D$2:$D$201,0.4) -> 5 | C23: ="El 40% de la muestra utiliza hasta "&ROUND(B23,2)&" horas de pantalla." -> El 40% de la muestra utiliza hasta 5 horas de pantalla.
A24: D9 | B24: =PERCENTILE(Datos_limpios_200!$D$2:$D$201,0.9) -> 8.41 | C24: ="El 90% de la muestra utiliza hasta "&ROUND(B24,2)&" horas de pantalla." -> El 90% de la muestra utiliza hasta 8,41 horas de pantalla.
A25: P23 | B25: =PERCENTILE(Datos_limpios_200!$D$2:$D$201,0.23) -> 3.777 | C25: ="El 23% de la muestra utiliza hasta "&ROUND(B25,2)&" horas de pantalla." -> El 23% de la muestra utiliza hasta 3,78 horas de pantalla.
A26: P75 | B26: =PERCENTILE(Datos_limpios_200!$D$2:$D$201,0.75) -> 7.1 | C26: ="El 75% de la muestra utiliza hasta "&ROUND(B26,2)&" horas de pantalla." -> El 75% de la muestra utiliza hasta 7,1 horas de pantalla.
A27: P97 | B27: =PERCENTILE(Datos_limpios_200!$D$2:$D$201,0.97) -> 9.5 | C27: ="El 97% de la muestra utiliza hasta "&ROUND(B27,2)&" horas de pantalla." -> El 97% de la muestra utiliza hasta 9,5 horas de pantalla.

Sheet Frecuencias_pantalla
A1: Tabla completa de frecuencias - Horas promedio de pantalla por día
A3: Clase | B3: Límite inferior | C3: Límite superior | D3: Intervalo | E3: fi | F3: Fi | G3: fri | H3: Fri | I3: pi % | J3: Pi % | L3: Símbolo | M3: Interpretación
A4: 1 | B4: 0 | C4: 1 | D4: =IF(A4=12,B4&" a "&C4,B4&" a menos de "&C4) -> 0 a menos de 1 | E4: =IF(A4=12,COUNTIFS(Datos_limpios_200!$D$2:$D$201,">="&B4,Datos_limpios_200!$D$2:$D$201,"<="&C4),COUNTIFS(Datos_limpios_200!$D$2:$D$201,">="&B4,Datos_limpios_200!$D$2:$D$201,"<"&C4)) -> 0 | F4: =SUM($E$4:E4) -> 0 | G4: =E4/SUM($E$4:$E$15) -> 0 | H4: =F4/SUM($E$4:$E$15) -> 0 | I4: =G4*100 -> 0 | J4: =H4*100 -> 0 | L4: f₂ | M4: =L4&" = "&E5&": "&E5&" personas se ubican en el intervalo "&D5&" horas." -> f₂ = 1: 1 personas se ubican en el intervalo 1 a menos de 2 horas.
A5: 2 | B5: 1 | C5: 2 | D5: =IF(A5=12,B5&" a "&C5,B5&" a menos de "&C5) -> 1 a menos de 2 | E5: =IF(A5=12,COUNTIFS(Datos_limpios_200!$D$2:$D$201,">="&B5,Datos_limpios_200!$D$2:$D$201,"<="&C5),COUNTIFS(Datos_limpios_200!$D$2:$D$201,">="&B5,Datos_limpios_200!$D$2:$D$201,"<"&C5)) -> 1 | F5: =SUM($E$4:E5) -> 1 | G5: =E5/SUM($E$4:$E$15) -> 0.005 | H5: =F5/SUM($E$4:$E$15) -> 0.005 | I5: =G5*100 -> 0.5 | J5: =H5*100 -> 0.5 | L5: f₅ | M5: =L5&" = "&E8&": "&E8&" personas se ubican en el intervalo "&D8&" horas." -> f₅ = 22: 22 personas se ubican en el intervalo 4 a menos de 5 horas.
A6: 3 | B6: 2 | C6: 3 | D6: =IF(A6=12,B6&" a "&C6,B6&" a menos de "&C6) -> 2 a menos de 3 | E6: =IF(A6=12,COUNTIFS(Datos_limpios_200!$D$2:$D$201,">="&B6,Datos_limpios_200!$D$2:$D$201,"<="&C6),COUNTIFS(Datos_limpios_200!$D$2:$D$201,">="&B6,Datos_limpios_200!$D$2:$D$201,"<"&C6)) -> 21 | F6: =SUM($E$4:E6) -> 22 | G6: =E6/SUM($E$4:$E$15) -> 0.105 | H6: =F6/SUM($E$4:$E$15) -> 0.11 | I6: =G6*100 -> 10.5 | J6: =H6*100 -> 11 | L6: f₈ | M6: =L6&" = "&E11&": "&E11&" personas se ubican en el intervalo "&D11&" horas." -> f₈ = 23: 23 personas se ubican en el intervalo 7 a menos de 8 horas.
A7: 4 | B7: 3 | C7: 4 | D7: =IF(A7=12,B7&" a "&C7,B7&" a menos de "&C7) -> 3 a menos de 4 | E7: =IF(A7=12,COUNTIFS(Datos_limpios_200!$D$2:$D$201,">="&B7,Datos_limpios_200!$D$2:$D$201,"<="&C7),COUNTIFS(Datos_limpios_200!$D$2:$D$201,">="&B7,Datos_limpios_200!$D$2:$D$201,"<"&C7)) -> 32 | F7: =SUM($E$4:E7) -> 54 | G7: =E7/SUM($E$4:$E$15) -> 0.16 | H7: =F7/SUM($E$4:$E$15) -> 0.27 | I7: =G7*100 -> 16 | J7: =H7*100 -> 27 | L7: F₄ | M7: =L7&" = "&F7&": "&F7&" personas acumulan hasta el intervalo "&D7&" horas." -> F₄ = 54: 54 personas acumulan hasta el intervalo 3 a menos de 4 horas.
A8: 5 | B8: 4 | C8: 5 | D8: =IF(A8=12,B8&" a "&C8,B8&" a menos de "&C8) -> 4 a menos de 5 | E8: =IF(A8=12,COUNTIFS(Datos_limpios_200!$D$2:$D$201,">="&B8,Datos_limpios_200!$D$2:$D$201,"<="&C8),COUNTIFS(Datos_limpios_200!$D$2:$D$201,">="&B8,Datos_limpios_200!$D$2:$D$201,"<"&C8)) -> 22 | F8: =SUM($E$4:E8) -> 76 | G8: =E8/SUM($E$4:$E$15) -> 0.11 | H8: =F8/SUM($E$4:$E$15) -> 0.38 | I8: =G8*100 -> 11 | J8: =H8*100 -> 38 | L8: F₇ | M8: =L8&" = "&F10&": "&F10&" personas acumulan hasta el intervalo "&D10&" horas." -> F₇ = 144: 144 personas acumulan hasta el intervalo 6 a menos de 7 horas.
A9: 6 | B9: 5 | C9: 6 | D9: =IF(A9=12,B9&" a "&C9,B9&" a menos de "&C9) -> 5 a menos de 6 | E9: =IF(A9=12,COUNTIFS(Datos_limpios_200!$D$2:$D$201,">="&B9,Datos_limpios_200!$D$2:$D$201,"<="&C9),COUNTIFS(Datos_limpios_200!$D$2:$D$201,">="&B9,Datos_limpios_200!$D$2:$D$201,"<"&C9)) -> 30 | F9: =SUM($E$4:E9) -> 106 | G9: =E9/SUM($E$4:$E$15) -> 0.15 | H9: =F9/SUM($E$4:$E$15) -> 0.53 | I9: =G9*100 -> 15 | J9: =H9*100 -> 53 | L9: F₁₀ | M9: =L9&" = "&F13&": "&F13&" personas acumulan hasta el intervalo "&D13&" horas." -> F₁₀ = 199: 199 personas acumulan hasta el intervalo 9 a menos de 10 horas.
A10: 7 | B10: 6 | C10: 7 | D10: =IF(A10=12,B10&" a "&C10,B10&" a menos de "&C10) -> 6 a menos de 7 | E10: =IF(A10=12,COUNTIFS(Datos_limpios_200!$D$2:$D$201,">="&B10,Datos_limpios_200!$D$2:$D$201,"<="&C10),COUNTIFS(Datos_limpios_200!$D$2:$D$201,">="&B10,Datos_limpios_200!$D$2:$D$201,"<"&C10)) -> 38 | F10: =SUM($E$4:E10) -> 144 | G10: =E10/SUM($E$4:$E$15) -> 0.19 | H10: =F10/SUM($E$4:$E$15) -> 0.72 | I10: =G10*100 -> 19 | J10: =H10*100 -> 72 | L10: p₃ | M10: =L10&" = "&ROUND(I6,2)&"%: porcentaje de personas ubicadas en el intervalo "&D6&" horas." -> p₃ = 10,5%: porcentaje de personas ubicadas en el intervalo 2 a menos de 3 horas.
A11: 8 | B11: 7 | C11: 8 | D11: =IF(A11=12,B11&" a "&C11,B11&" a menos de "&C11) -> 7 a menos de 8 | E11: =IF(A11=12,COUNTIFS(Datos_limpios_200!$D$2:$D$201,">="&B11,Datos_limpios_200!$D$2:$D$201,"<="&C11),COUNTIFS(Datos_limpios_200!$D$2:$D$201,">="&B11,Datos_limpios_200!$D$2:$D$201,"<"&C11)) -> 23 | F11: =SUM($E$4:E11) -> 167 | G11: =E11/SUM($E$4:$E$15) -> 0.115 | H11: =F11/SUM($E$4:$E$15) -> 0.835 | I11: =G11*100 -> 11.5 | J11: =H11*100 -> 83.5 | L11: p₆ | M11: =L11&" = "&ROUND(I9,2)&"%: porcentaje de personas ubicadas en el intervalo "&D9&" horas." -> p₆ = 15%: porcentaje de personas ubicadas en el intervalo 5 a menos de 6 horas.
A12: 9 | B12: 8 | C12: 9 | D12: =IF(A12=12,B12&" a "&C12,B12&" a menos de "&C12) -> 8 a menos de 9 | E12: =IF(A12=12,COUNTIFS(Datos_limpios_200!$D$2:$D$201,">="&B12,Datos_limpios_200!$D$2:$D$201,"<="&C12),COUNTIFS(Datos_limpios_200!$D$2:$D$201,">="&B12,Datos_limpios_200!$D$2:$D$201,"<"&C12)) -> 19 | F12: =SUM($E$4:E12) -> 186 | G12: =E12/SUM($E$4:$E$15) -> 0.095 | H12: =F12/SUM($E$4:$E$15) -> 0.93 | I12: =G12*100 -> 9.5 | J12: =H12*100 -> 93 | L12: p₉ | M12: =L12&" = "&ROUND(I12,2)&"%: porcentaje de personas ubicadas en el intervalo "&D12&" horas." -> p₉ = 9,5%: porcentaje de personas ubicadas en el intervalo 8 a menos de 9 horas.
A13: 10 | B13: 9 | C13: 10 | D13: =IF(A13=12,B13&" a "&C13,B13&" a menos de "&C13) -> 9 a menos de 10 | E13: =IF(A13=12,COUNTIFS(Datos_limpios_200!$D$2:$D$201,">="&B13,Datos_limpios_200!$D$2:$D$201,"<="&C13),COUNTIFS(Datos_limpios_200!$D$2:$D$201,">="&B13,Datos_limpios_200!$D$2:$D$201,"<"&C13)) -> 13 | F13: =SUM($E$4:E13) -> 199 | G13: =E13/SUM($E$4:$E$15) -> 0.065 | H13: =F13/SUM($E$4:$E$15) -> 0.995 | I13: =G13*100 -> 6.5 | J13: =H13*100 -> 99.5 | L13: P₈ | M13: =L13&" = "&ROUND(J11,2)&"%: porcentaje acumulado hasta el intervalo "&D11&" horas." -> P₈ = 83,5%: porcentaje acumulado hasta el intervalo 7 a menos de 8 horas.
A14: 11 | B14: 10 | C14: 11 | D14: =IF(A14=12,B14&" a "&C14,B14&" a menos de "&C14) -> 10 a menos de 11 | E14: =IF(A14=12,COUNTIFS(Datos_limpios_200!$D$2:$D$201,">="&B14,Datos_limpios_200!$D$2:$D$201,"<="&C14),COUNTIFS(Datos_limpios_200!$D$2:$D$201,">="&B14,Datos_limpios_200!$D$2:$D$201,"<"&C14)) -> 1 | F14: =SUM($E$4:E14) -> 200 | G14: =E14/SUM($E$4:$E$15) -> 0.005 | H14: =F14/SUM($E$4:$E$15) -> 1 | I14: =G14*100 -> 0.5 | J14: =H14*100 -> 100 | L14: P₁₂ | M14: =L14&" = "&ROUND(J15,2)&"%: porcentaje acumulado hasta el intervalo "&D15&" horas." -> P₁₂ = 100%: porcentaje acumulado hasta el intervalo 11 a 12 horas.
A15: 12 | B15: 11 | C15: 12 | D15: =IF(A15=12,B15&" a "&C15,B15&" a menos de "&C15) -> 11 a 12 | E15: =IF(A15=12,COUNTIFS(Datos_limpios_200!$D$2:$D$201,">="&B15,Datos_limpios_200!$D$2:$D$201,"<="&C15),COUNTIFS(Datos_limpios_200!$D$2:$D$201,">="&B15,Datos_limpios_200!$D$2:$D$201,"<"&C15)) -> 0 | F15: =SUM($E$4:E15) -> 200 | G15: =E15/SUM($E$4:$E$15) -> 0 | H15: =F15/SUM($E$4:$E$15) -> 1 | I15: =G15*100 -> 0 | J15: =H15*100 -> 100
D16: Total | E16: =SUM(E4:E15) -> 200 | G16: =SUM(G4:G15) -> 1 | I16: =SUM(I4:I15) -> 100

Sheet Regresion_lineal
A1: Regresión lineal - Redes sociales y rendimiento académico
A3: Variable independiente (x) | B3: Horas promedio de redes sociales por día | D3: Horas redes sociales (x) | E3: Rendimiento académico (y)
A4: Recta de regresión | B4: ="y = "&ROUND(INTERCEPT(Datos_limpios_200!$J$2:$J$201,Datos_limpios_200!$I$2:$I$201),3)&" + ("&ROUND(SLOPE(Datos_limpios_200!$J$2:$J$201,Datos_limpios_200!$I$2:$I$201),3)&")x" -> y = 6,617 + (-0,244)x | D4: 3 | E4: 7
A5: Pendiente | B5: =SLOPE(Datos_limpios_200!$J$2:$J$201,Datos_limpios_200!$I$2:$I$201) -> -0.24401748 | D5: 3.5 | E5: 5
A6: Coeficiente de correlación r | B6: =CORREL(Datos_limpios_200!$I$2:$I$201,Datos_limpios_200!$J$2:$J$201) -> -0.19410584 | D6: 5 | E6: 10
A7: Coeficiente de determinación R² | B7: =RSQ(Datos_limpios_200!$J$2:$J$201,Datos_limpios_200!$I$2:$I$201) -> 0.037677078 | D7: 5 | E7: 7
A8: Interpretación general | B8: =IF(B6<0,"La relación observada es negativa: a mayor cantidad de horas en redes sociales, el rendimiento académico tiende a disminuir en esta muestra.","La relación observada es positiva: a mayor cantidad de horas en redes sociales, el rendimiento académico tiende a aumentar en esta muestra.") -> La relación observada es negativa: a mayor cantidad de horas en redes sociales, el rendimiento académico tiende a disminuir en esta muestra. | D8: 1.4 | E8: 7
A9: Interpretación general | B9: La relación observada es negativa: a mayor cantidad de horas en redes sociales, el rendimiento académico tiende a disminuir en esta muestra. | D9: 3.8 | E9: 7
D10: 3.4 | E10: 6
D11: 2.9 | E11: 6
D12: 2 | E12: 8
D13: 1.6 | E13: 6
D14: 1.8 | E14: 6
D15: 2.7 | E15: 6
D16: 3.5 | E16: 7
D17: 2.9 | E17: 7
D18: 3.3 | E18: 6
D19: 1.7 | E19: 8
D20: 7.3 | E20: 3
D21: 5.2 | E21: 5
... D203: 4 | E203: 10

Sheet Datos_catedra
A1: Horas de redes sociales por día | B1: Rendimiento académico
A2: 5 | B2: 7
A3: 1 | B3: 8
A4: 3 | B4: 8
A5: 3 | B5: 8
A6: 6 | B6: 7
A7: 5 | B7: 7
A8: 7 | B8: 7
A9: 2 | B9: 8
A10: 4 | B10: 7
A11: 1 | B11: 8
A12: 3 | B12: 7
A13: 4 | B13: 7
... A491: 5 | B491: 7

Sheet Frecuencias_catedra
A1: Tabla completa de frecuencias - Base de datos proporcionada por la cátedra
A3: xi (horas/día) | B3: fi | C3: Fi | D3: fri | E3: Fri | F3: pi % | G3: Pi % | I3: Medida | J3: Resultado | K3: Interpretación
A4: 0 | B4: =COUNTIF(Datos_catedra!$A$2:$A$491,A4) -> 11 | C4: =SUM($B$4:B4) -> 11 | D4: =B4/SUM($B$4:$B$16) -> 0.02244898 | E4: =C4/SUM($B$4:$B$16) -> 0.02244898 | F4: =D4*100 -> 2.244898 | G4: =E4*100 -> 2.244898 | I4: Media aritmética | J4: =AVERAGE(Datos_catedra!$A$2:$A$491) -> 4.4734694 | K4: Promedio de horas de redes sociales por día.
A5: 1 | B5: =COUNTIF(Datos_catedra!$A$2:$A$491,A5) -> 18 | C5: =SUM($B$4:B5) -> 29 | D5: =B5/SUM($B$4:$B$16) -> 0.036734694 | E5: =C5/SUM($B$4:$B$16) -> 0.059183673 | F5: =D5*100 -> 3.6734694 | G5: =E5*100 -> 5.9183673 | I5: Mediana | J5: =MEDIAN(Datos_catedra!$A$2:$A$491) -> 4 | K5: El 50% de la base se ubica por debajo o igual a este valor.
A6: 2 | B6: =COUNTIF(Datos_catedra!$A$2:$A$491,A6) -> 52 | C6: =SUM($B$4:B6) -> 81 | D6: =B6/SUM($B$4:$B$16) -> 0.10612245 | E6: =C6/SUM($B$4:$B$16) -> 0.16530612 | F6: =D6*100 -> 10.612245 | G6: =E6*100 -> 16.530612 | I6: Moda | J6: =INDEX($A$4:$A$16,MATCH(MAX($B$4:$B$16),$B$4:$B$16,0)) -> 3 | K6: Valor que más se repite.
A7: 3 | B7: =COUNTIF(Datos_catedra!$A$2:$A$491,A7) -> 102 | C7: =SUM($B$4:B7) -> 183 | D7: =B7/SUM($B$4:$B$16) -> 0.20816327 | E7: =C7/SUM($B$4:$B$16) -> 0.37346939 | F7: =D7*100 -> 20.816327 | G7: =E7*100 -> 37.346939 | I7: Varianza | J7: =SUMPRODUCT($B$4:$B$16,($A$4:$A$16-J4)*($A$4:$A$16-J4))/(SUM($B$4:$B$16)-1) -> 5.035082 | K7: Dispersión cuadrática promedio muestral.
A8: 4 | B8: =COUNTIF(Datos_catedra!$A$2:$A$491,A8) -> 92 | C8: =SUM($B$4:B8) -> 275 | D8: =B8/SUM($B$4:$B$16) -> 0.1877551 | E8: =C8/SUM($B$4:$B$16) -> 0.56122449 | F8: =D8*100 -> 18.77551 | G8: =E8*100 -> 56.122449 | I8: Desvío estándar | J8: =SQRT(J7) -> 2.2438988 | K8: Alejamiento promedio respecto de la media.
A9: 5 | B9: =COUNTIF(Datos_catedra!$A$2:$A$491,A9) -> 81 | C9: =SUM($B$4:B9) -> 356 | D9: =B9/SUM($B$4:$B$16) -> 0.16530612 | E9: =C9/SUM($B$4:$B$16) -> 0.72653061 | F9: =D9*100 -> 16.530612 | G9: =E9*100 -> 72.653061 | I9: Coeficiente de variación | J9: =J8/J4 -> 0.50160147 | K9: Variabilidad relativa respecto de la media.
A10: 6 | B10: =COUNTIF(Datos_catedra!$A$2:$A$491,A10) -> 44 | C10: =SUM($B$4:B10) -> 400 | D10: =B10/SUM($B$4:$B$16) -> 0.089795918 | E10: =C10/SUM($B$4:$B$16) -> 0.81632653 | F10: =D10*100 -> 8.9795918 | G10: =E10*100 -> 81.632653 | I10: Asimetría | J10: =SKEW(Datos_catedra!$A$2:$A$491) -> 0.66313034 | K10: Indica inclinación de la distribución.
A11: 7 | B11: =COUNTIF(Datos_catedra!$A$2:$A$491,A11) -> 45 | C11: =SUM($B$4:B11) -> 445 | D11: =B11/SUM($B$4:$B$16) -> 0.091836735 | E11: =C11/SUM($B$4:$B$16) -> 0.90816327 | F11: =D11*100 -> 9.1836735 | G11: =E11*100 -> 90.816327 | I11: Curtosis | J11: =KURT(Datos_catedra!$A$2:$A$491) -> 0.53022052 | K11: Indica concentración o achatamiento de los datos.
A12: 8 | B12: =COUNTIF(Datos_catedra!$A$2:$A$491,A12) -> 17 | C12: =SUM($B$4:B12) -> 462 | D12: =B12/SUM($B$4:$B$16) -> 0.034693878 | E12: =C12/SUM($B$4:$B$16) -> 0.94285714 | F12: =D12*100 -> 3.4693878 | G12: =E12*100 -> 94.285714
A13: 9 | B13: =COUNTIF(Datos_catedra!$A$2:$A$491,A13) -> 14 | C13: =SUM($B$4:B13) -> 476 | D13: =B13/SUM($B$4:$B$16) -> 0.028571429 | E13: =C13/SUM($B$4:$B$16) -> 0.97142857 | F13: =D13*100 -> 2.8571429 | G13: =E13*100 -> 97.142857
A14: 10 | B14: =COUNTIF(Datos_catedra!$A$2:$A$491,A14) -> 7 | C14: =SUM($B$4:B14) -> 483 | D14: =B14/SUM($B$4:$B$16) -> 0.014285714 | E14: =C14/SUM($B$4:$B$16) -> 0.98571429 | F14: =D14*100 -> 1.4285714 | G14: =E14*100 -> 98.571429
A15: 11 | B15: =COUNTIF(Datos_catedra!$A$2:$A$491,A15) -> 4 | C15: =SUM($B$4:B15) -> 487 | D15: =B15/SUM($B$4:$B$16) -> 0.0081632653 | E15: =C15/SUM($B$4:$B$16) -> 0.99387755 | F15: =D15*100 -> 0.81632653 | G15: =E15*100 -> 99.387755
A16: 12 | B16: =COUNTIF(Datos_catedra!$A$2:$A$491,A16) -> 3 | C16: =SUM($B$4:B16) -> 490 | D16: =B16/SUM($B$4:$B$16) -> 0.006122449 | E16: =C16/SUM($B$4:$B$16) -> 1 | F16: =D16*100 -> 0.6122449 | G16: =E16*100 -> 100
A17: TOTAL | B17: 490 | D17: 1 | F17: 100

Sheet Comparacion_catedra
A1: Contrastación de datos - Muestra propia vs Base de la cátedra
A3: Medida | B3: Muestra propia | C3: Base de la cátedra | D3: Diferencia | E3: Interpretación
A4: Cantidad de casos | B4: =COUNTA(Datos_limpios_200!A2:A201) -> 200 | C4: =COUNTA(Datos_catedra!A2:A491) -> 490 | E4: La base de la cátedra contiene mayor cantidad de registros.
A5: Media de horas de redes sociales por día | B5: =AVERAGE(Datos_limpios_200!I2:I201) -> 3.9225 | C5: =AVERAGE(Datos_catedra!A2:A491) -> 4.4734694 | D5: =C5-B5 -> 0.55096939 | E5: La base de la cátedra presenta un promedio mayor.
A6: Mediana | B6: =MEDIAN(Datos_limpios_200!I2:I201) -> 3.5 | C6: =MEDIAN(Datos_catedra!A2:A491) -> 4 | D6: =C6-B6 -> 0.5 | E6: Compara el valor central de ambas bases.
A7: Desvío estándar | B7: =SQRT(SUMPRODUCT((Datos_limpios_200!$I$2:$I$201-B5)*(Datos_limpios_200!$I$2:$I$201-B5))/(B4-1)) -> 1.9262127 | C7: =Frecuencias_catedra!J8 -> 2.2438988 | D7: =C7-B7 -> 0.31768618 | E7: Permite comparar la dispersión de los datos.
A8: Coeficiente de correlación lineal | B8: =-0.194 -> -0.194 | C8: =CORREL(Datos_catedra!A2:A491,Datos_catedra!B2:B491) -> -0.58307785 | D8: =C8-B8 -> -0.38907785 | E8: La relación negativa es más fuerte en la base de la cátedra.
A10: Recta de regresión base cátedra | B10: y = -0.219x + 8.057
A11: Coeficiente de correlación r | B11: -0.583
A12: Coeficiente de determinación R² | B12: 0.340
